Workbook

Sheet README
B2: PRIVATE LABEL 2-PLY BATH TISSUE
B3: Sourcing Tracker + Landed Cost Model
B5: HOW TO USE THIS WORKBOOK
B6: 1. Assumptions | C6: Start here. Every yellow-filled cell is yours to edit. Everything downstream recalculates. The spec block drives roll weight and cube, which drive freight, which drives everything.
B7: 2. Supplier Tracker | C7: Your sourcing spreadsheet. Pre-loaded with 12 real converters. Fill the blue quote columns as responses come in; the weighted score ranks them automatically.
B8: 3. Landed Cost Model | C8: Full cost stack for one customer order, from parent roll to doorstep. Change pack size and zone at the top.
B9: 4. Scenario - Pack x Zone | C9: The core answer: delivered cost per 100 sheets AND gross margin, flexed by rolls per pack (rows) and parcel zone (columns).
B10: 5. Scenario - Volume | C10: Procurement view: how ex-works + inbound freight per roll moves with order size and freight mode (LTL / TL / Ocean).
B11: 6. Freight Rates | C11: Parcel rate table by billed weight and zone. THESE ARE PLANNING ESTIMATES - replace with your carrier contract before committing.
B12: 7. Benchmark | C12: Cost per 100 sheets vs Kirkland, AmazonCommercial, store brand and Charmin. Your modeled number pulls through live.
B14: COLOR KEY
B15: Yellow fill + blue text | C15: INPUT - you edit these. Nothing else.
B16: Black text | C16: Formula. Do not overwrite.
B17: Green text | C17: Link pulled from another sheet.
B18: Green fill | C18: Key output.
B20: THE ONE NUMBER THAT MATTERS
B21: Cost per 100 sheets | C21: Roll counts and 'Mega roll' math are marketing. Cost per 100 sheets is the only honest unit of comparison, and it is what this model optimizes. Market floor is ~$0.18/100 sheets (Kirkland, AmazonCommercial). National brands sit at $0.30-$0.45.
B23: CRITICAL MODELING NOTE - DIMENSIONAL WEIGHT
B24: Why compression matters | C24: Bath tissue is ~95% air. Carriers bill the GREATER of actual and dimensional weight, so an uncompressed 30-roll pack bills at roughly 17 lb against 7 lb of actual weight. The 'Compression saving' input on the Assumptions tab is the single highest-leverage lever in this workbook. Ask every converter about compressed/high-density winding.
B26: SOURCES FOR PRE-FILLED DEFAULTS
B27: Parent roll $/ton | C27: Recycled/mixed $900-1,050; standard virgin $950-1,200; premium virgin $1,200-1,300+. Fastmarkets US tissue parent roll assessments and Roxipaper 2026 B2B jumbo roll price guide. Default set to $1,000.
B28: Rolls per pallet | C28: 1,920 rolls per pallet - observed pallet-lot listing (1001 Pallet Liquidation).
B29: Rolls per 40ft container | C29: 56,160 rolls. Source: Accio wholesale toilet paper roll sourcing guide.
B30: MOQ range | C30: 500 to 250,000 rolls across the market; most converters price wholesale at 10,000+ rolls. Source: Accio; Top Source Hygiene 2026 landed cost & ROI guide.
B31: Benchmark retail prices | C31: Kirkland Signature 30x380 at $20.99 = $0.184/100 sheets; AmazonCommercial 36x286 at $18.54 S&S = ~$0.18/100 sheets. Slickdeals, Everyday Cheapskate, Who Gives A Crap cost-per-sheet analysis.
B32: Parcel rates | C32: ESTIMATES ONLY, built to approximate published ground rates including fuel and residential surcharge. Not quoted. Replace before use.
B33: DIM divisor 139 | C33: Standard retail ground DIM divisor. Negotiated contracts commonly reach 166 - if you get 166, change the input; it is worth real money.
B35: BUILT
B36: Date | C36: 28 July 2026
B37: Scope | C37: 2-ply, 4.0in x 4.0in sheet, 300 sheets/roll value grade, US retail / DTC.

Sheet Assumptions
B2: MASTER ASSUMPTIONS
B3: Edit yellow cells only. Everything else is formula-driven.
B5: 1. PRODUCT SPECIFICATION
B6: Sheet width | C6: 4 | D6: in | E6: Spec a FULL 4.0in sheet. National brands have shrunk below this - it is your anti-shrinkflation claim.
B7: Sheet length | C7: 4 | D7: in
B8: Sheets per roll | C8: 300 | D8: sheets
B9: Plies | C9: 2 | D9: ply
B10: Basis weight per ply | C10: 14 | D10: gsm | E10: 13-15 gsm is the value-grade 2-ply band. Below 13 you lose the 'same quality as name brands' claim.
B11: Core weight | C11: 5 | D11: g
B12: Roll diameter (uncompressed) | C12: 4.5 | D12: in
B13: Sheet area | C13: =$C$6*$C$7 -> 16 | D13: sq in
B14: Sheet area | C14: =$C$13*0.00064516 -> 0.01032256 | D14: sq m | E14: 1 sq in = 0.00064516 sq m
B15: Total basis weight (all plies) | C15: =$C$10*$C$9 -> 28 | D15: gsm
B16: Fiber weight per roll | C16: =$C$14*$C$15*$C$8 -> 86.709504 | D16: g
B17: Total roll weight (incl. core) | C17: =$C$16+$C$11 -> 91.709504 | D17: g
B18: Roll weight | C18: =$C$17/453.592 -> 0.20218501 | D18: lb | E18: 1 lb = 453.592 g
B19: Square feet per roll | C19: =$C$13*$C$8/144 -> 33.333333 | D19: sq ft | E19: Print this on the front of the pack.
B21: 2. EX-WORKS COST BUILD-UP
B22: Parent roll price | C22: 1000 | D22: $/short ton | E22: Recycled/mixed $900-1,050. Standard virgin $950-1,200. Premium virgin $1,200-1,300+.
B23: Pounds per short ton | C23: 2000 | D23: lb
B24: Fiber cost per roll | C24: =($C$16/453.592)*($C$22/$C$23) -> 0.095580945 | D24: $/roll
B25: Converting, labor & waste uplift | C25: 0.6 | D25: % | E25: Converting typically adds 60-100% on top of fiber. Push back on any quote implying more.
B26: Core + wrap + label | C26: 0.02 | D26: $/roll
B27: Modeled ex-works cost | C27: =$C$24*(1+$C$25)+$C$26 -> 0.17292951 | D27: $/roll | E27: Target band: $0.18-$0.24/roll.
B28: ACTUAL QUOTED ex-works (0 = use model) | C28: 0 | D28: $/roll | E28: Once a converter quotes you, enter it here and the whole model switches to the real number.
B29: EX-WORKS COST USED | C29: =IF($C$28>0,$C$28,$C$27) -> 0.17292951 | D29: $/roll
B31: 3. PACK CONFIGURATION & CUBE
B32: Rolls per pack (base case) | C32: 30 | D32: rolls | E32: Never dropship below 24. Small packs lose money on every order.
B33: Compression saving vs uncompressed | C33: 0.3 | D33: % | E33: HIGHEST-LEVERAGE INPUT IN THE MODEL. Compressed winding cuts cube ~30% at identical sheet count.
B34: Carton tare weight | C34: 0.6 | D34: lb | E34: Design the retail carton AS the shipper - saves a box, void fill and a labor step.
B35: DIM divisor | C35: 139 | E35: 139 = standard retail ground. Negotiate to 166 if you can; it is worth real money on this product.
B36: Bounding cube per roll | C36: =$C$12*$C$12*$C$6 -> 81 | D36: cu in
B37: Pack actual weight | C37: =$C$32*$C$18+$C$34 -> 6.6655504 | D37: lb
B38: Pack cube (compressed) | C38: =$C$32*$C$36*(1-$C$33) -> 1701 | D38: cu in
B39: Pack DIM weight | C39: =$C$38/$C$35 -> 12.23741 | D39: lb
B40: PACK BILLED WEIGHT | C40: =MAX($C$37,$C$39) -> 12.23741 | D40: lb | E40: Carrier bills the greater of actual and DIM.
B42: 4. INBOUND FREIGHT (converter to your 3PL)
B43: Freight mode | C43: TL | E43: Enter exactly: LTL, TL or OCEAN
B44: Rolls per pallet | C44: 1920 | D44: rolls
B45: Pallets per 53ft trailer | C45: 26 | D45: pallets
...

Sheet Supplier Tracker
A1: SUPPLIER / CONVERTER TRACKER
A2: Blue columns = you fill in as quotes arrive. Score S1-S5 on a 1-5 scale (5 = best). Weighted score ranks the field. | P2: Weights >> | Q2: 0.4 | R2: 0.2 | S2: 0.15 | T2: 0.15 | U2: 0.1 | V2: =SUM(Q2:U2) -> 1
A4: Supplier | B4: Tier | C4: Country | D4: Location / Plants | E4: Website | F4: Private Label? | G4: Published MOQ | H4: Quoted MOQ (rolls) | I4: $/roll @ 10k | J4: $/roll @ 50k | K4: $/roll @ 1 TL | L4: Setup / plate fee | M4: Lead time (wks) | N4: Compressed wind? | O4: Blind ship? | P4: Sample recd | Q4: S1 Price | R4: S2 MOQ fit | S4: S3 Blind ship | T4: S4 Compression | U4: S5 Lead time | V4: WEIGHTED SCORE | W4: Status | X4: Notes
A5: Royal Paper | B5: 1 | C5: USA | D5: Phoenix AZ + South Carolina | E5: royalpaper.us/private-label/ | F5: Yes - core business | G5: Request | V5: =IFERROR(SUMPRODUCT(Q5:U5,$Q$2:$U$2),0) -> 0 | W5: Not contacted | X5: Largest privately-owned US private-label tissue producer. Dual-coast plants let you run East+West 3PL off ONE supplier. START HERE.
A6: Global Tissue Group | B6: 1 | C6: USA | D6: Hauppauge NY | E6: globaltissuegroup.com/private-brand-solutions | F6: Yes - core business | G6: Request | V6: =IFERROR(SUMPRODUCT(Q6:U6,$Q$2:$U$2),0) -> 0 | W6: Not contacted | X6: Private brand + contract manufacturing is their entire model. Explicitly positions to help brands compete with nationals. Best East Coast partner.
A7: Domtar Tissue | B7: 1 | C7: USA | D7: Multiple US mills | E7: domtar.com/tissue/retail-private-label-tissue-towel/ | F7: Yes - retail private label div. | G7: Request | V7: =IFERROR(SUMPRODUCT(Q7:U7,$Q$2:$U$2),0) -> 0 | W7: Not contacted | X7: Markets 'name-brand equivalent' bath tissue for private brand programs - literally your brief. Integrated pulp = stable pricing.
A8: Solaris Paper | B8: 1 | C8: USA | D8: Green Bay WI (Asia Pulp & Paper NA) | E8: solarispaper.com | F8: Yes - premium private brand | G8: Request | V8: =IFERROR(SUMPRODUCT(Q8:U8,$Q$2:$U$2),0) -> 0 | W8: Not contacted | X8: APP-backed, deepest fiber integration in the group. Most stable pricing if pulp rises. Best for scale-up phase.
A9: Von Drehle | B9: 1 | C9: USA | D9: Hickory NC / Cordova TN | E9: vondrehle.com | F9: Yes | G9: Request | V9: =IFERROR(SUMPRODUCT(Q9:U9,$Q$2:$U$2),0) -> 0 | W9: Not contacted | X9: Family-owned, aggressive on value grades, strong away-from-home crossover.
A10: First Quality Enterprises | B10: 1 | C10: USA | D10: Lock Haven PA | E10: firstquality.com | F10: Yes - flexible programs | G10: Request | V10: =IFERROR(SUMPRODUCT(Q10:U10,$Q$2:$U$2),0) -> 0 | W10: Not contacted | X10: ISO-certified, flexible private label programs. Retail and healthcare.
A11: Marcal | B11: 1 | C11: USA | D11: Elmwood Park NJ | E11: marcalpaper.com | F11: Yes | G11: Request | V11: =IFERROR(SUMPRODUCT(Q11:U11,$Q$2:$U$2),0) -> 0 | W11: Not contacted | X11: 100% recycled. Costs slightly more but hands you a sustainability story with a 70-year American mill pedigree behind it.
A12: Select Products Holdings | B12: 2 | C12: USA | D12: USA | E12: selectproductsholdings.com | F12: Yes - private label only | G12: Request | V12: =IFERROR(SUMPRODUCT(Q12:U12,$Q$2:$U$2),0) -> 0 | W12: Not contacted | X12: Full-service converter, private-label consumer tissue exclusively.
A13: E&L Tissue Paper | B13: 2 | C13: USA | D13: Cleveland OH | E13: paperindex.com (profile) | F13: Yes | G13: Lower - ask | V13: =IFERROR(SUMPRODUCT(Q13:U13,$Q$2:$U$2),0) -> 0 | W13: Not contacted | X13: Smaller converter, 1-ply and 2-ply bath tissue. Good candidate for a sub-10k pilot run.
A14: Berk International | B14: 2 | C14: USA | D14: Wilmington DE | E14: berkwiper.com/bulk-tissue-paper/ | F14: Yes + contract converting | G14: Lower - ask | V14: =IFERROR(SUMPRODUCT(Q14:U14,$Q$2:$U$2),0) -> 0 | W14: Not contacted | X14: 1-ply and 2-ply, made in USA, private label plus contract converting. Pilot-friendly.
A15: NL Bamboo | B15: 3 | C15: China | D15: China | E15: nlbamboo.com/solutions/retail-ecommerce-tissue-supply/ | F15: Yes - OEM/private label | G15: Low - from ~500 | V15: =IFERROR(SUMPRODUCT(Q15:U15,$Q$2:$U$2),0) -> 0 | W15: Not contacted | X15: Dedicated retail/ecommerce program: spec dev, sampling, packaging execution. BAMBOO PRICES PREMIUM - use for process support, not the budget SKU.
A16: Doba (reference only) | B16: 3 | C16: USA | D16: Aggregator | E16: doba.com/dropshipping/toilet-paper.html | F16: NO - generic catalog | G16: None | V16: =IFERROR(SUMPRODUCT(Q16:U16,$Q$2:$U$2),0) -> 0 | W16: Not contacted | X16: True no-MOQ dropship but generic product; you CANNOT brand it. Arbitrage, not brand-building. Listed for completeness - does not serve the brief.
A18: SCORING GUIDE (enter 1-5, where 5 = best):
A19: S1 Price - 5 = at or below $0.20/roll ex-works; 1 = above $0.30
A20: S2 MOQ fit - 5 = will run under 10,000 rolls; 1 = truckload minimum only
A21: S3 Blind ship - 5 = will hold your branded stock and blind-ship to consumers; 1 = pallet-out only
A22: S4 Compression - 5 = compressed/high-density winding available; 1 = uncompressed only
A23: S5 Lead time - 5 = under 4 weeks; 1 = over 12 weeks
A25: SOURCES
A26: Supplier capabilities per company websites and ThomasNet / PaperIndex listings, accessed July 2026.
A27: MOQ market range (500 - 250,000 rolls; wholesale pricing typically at 10,000+): Accio wholesale toilet paper sourcing guide; Top Source Hygiene 2026 landed cost guide.
A28: Tier 1 = domestic private-label converter, recommended for volume. Tier 2 = smaller converter, pilot-friendly. Tier 3 = offshore / aggregator.

Sheet Freight Rates
A1: PARCEL GROUND RATE TABLE
A2: PLANNING ESTIMATES ONLY - replace every cell with your negotiated carrier contract before committing capital.
A4: Billed weight (lb) | B4: 2 | C4: 3 | D4: 4 | E4: 5 | F4: 6 | G4: 7 | H4: 8
A5: 1 | B5: 8.2 | C5: 8.55 | D5: 9.05 | E5: 9.6 | F5: 10.2 | G5: 10.85 | H5: 11.5
A6: 3 | B6: 8.55 | C6: 8.95 | D6: 9.5 | E6: 10.1 | F6: 10.75 | G6: 11.45 | H6: 12.2
A7: 5 | B7: 8.9 | C7: 9.3 | D7: 9.9 | E7: 10.6 | F7: 11.3 | G7: 12.1 | H7: 12.9
A8: 10 | B8: 9.8 | C8: 10.4 | D8: 11.3 | E8: 12.3 | F8: 13.3 | G8: 14.4 | H8: 15.5
A9: 15 | B9: 10.9 | C9: 11.7 | D9: 12.9 | E9: 14.2 | F9: 15.6 | G9: 17 | H9: 18.5
A10: 20 | B10: 12.1 | C10: 13.1 | D10: 14.6 | E10: 16.3 | F10: 18 | G10: 19.8 | H10: 21.7
A11: 25 | B11: 13.4 | C11: 14.6 | D11: 16.4 | E11: 18.4 | F11: 20.5 | G11: 22.7 | H11: 24.9
A12: 30 | B12: 14.6 | C12: 16 | D12: 18.1 | E12: 20.4 | F12: 22.8 | G12: 25.3 | H12: 27.9
A13: 40 | B13: 17.2 | C13: 19.1 | D13: 21.8 | E13: 24.8 | F13: 27.9 | G13: 31.2 | H13: 34.6
A15: Lookup uses MATCH type 1 (nearest weight break at or below billed weight), so weight breaks must stay in ascending order.
A16: The 1 lb break exists so small packs still price at the carrier minimum. Without it the lookup returns nothing and small packs look free - which they are not.
A17: Rates are modeled to approximate published ground rates inclusive of fuel and residential surcharge. They are NOT quoted rates.
A18: Bulky-item reality check: DIM charges commonly inflate cost 20-30%, and packages over 50 lb or 108in length+girth add $15-40 in surcharges.
A19: Multi-warehouse (East + West) typically cuts postage 15-25% by shifting orders from Zone 7-8 to Zone 1-3.

Sheet Landed Cost Model
B2: LANDED COST MODEL - ONE CUSTOMER ORDER
B3: Parent roll to doorstep. Change the two yellow cells below; everything recalculates.
B5: SCENARIO LEVERS
B6: Rolls per pack | C6: 30 | D6: rolls | E6: Override the base case here without touching the Assumptions tab.
B7: Parcel zone | C7: 5 | D7: zone 2-8 | E7: Zone 2-3 = regional. Zone 7-8 = cross-country. This is why you split inventory East and West.
B9: A. UNIT ECONOMICS - PER ROLL
B10: Ex-works cost per roll | C10: =Assumptions!$C$29 -> 0.17292951 | D10: $/roll
B11: Inbound freight per roll | C11: =Assumptions!$C$51 -> 0.056089744 | D11: $/roll
B12: Duty per roll | C12: =Assumptions!$C$52 -> 0 | D12: $/roll
B13: Storage per roll | C13: =Assumptions!$C$60 -> 0.011458333 | D13: $/roll
B14: Total cost per roll (pre-fulfillment) | C14: =$C$10+$C$11+$C$12+$C$13 -> 0.24047759 | D14: $/roll
B16: B. PACK PHYSICS
B17: Pack actual weight | C17: =$C$6*Assumptions!$C$18+Assumptions!$C$34 -> 6.6655504 | D17: lb
B18: Pack cube (compressed) | C18: =$C$6*Assumptions!$C$36*(1-Assumptions!$C$33) -> 1701 | D18: cu in
B19: Pack DIM weight | C19: =$C$18/Assumptions!$C$35 -> 12.23741 | D19: lb
B20: BILLED WEIGHT | C20: =MAX($C$17,$C$19) -> 12.23741 | D20: lb | E20: Carrier bills the greater of the two. Note how far DIM exceeds actual.
B21: DIM penalty (billed vs actual) | C21: =IFERROR($C$20/$C$17-1,0) -> 0.83591893 | D21: % | E21: If this is large, compression is where your money is.
B23: C. COST STACK - PER ORDER
B24: Goods (ex-works) | C24: =$C$6*$C$10 -> 5.1878854 | D24: $
B25: Inbound freight | C25: =$C$6*$C$11 -> 1.6826923 | D25: $
B26: Duty | C26: =$C$6*$C$12 -> 0 | D26: $
B27: Storage | C27: =$C$6*$C$13 -> 0.34375 | D27: $
B28: Pick & pack | C28: =Assumptions!$C$56 -> 3.25 | D28: $
B29: Label & packaging | C29: =Assumptions!$C$57 -> 0.35 | D29: $
B30: Outbound parcel | C30: =IFERROR(INDEX('Freight Rates'!$B$5:$H$13,MATCH($C$20,'Freight Rates'!$A$5:$A$13,1),MATCH($C$7,'Freight Rates'!$B$4:$H$4,0)),0) -> 12.3 | D30: $ | E30: Looked up from the Freight Rates tab by billed weight and zone.
B31: TOTAL DELIVERED COST | C31: =SUM($C$24:$C$30) -> 23.114328 | D31: $
B33: D. THE HEADLINE NUMBER
B34: Sheets per pack | C34: =$C$6*Assumptions!$C$8 -> 9000 | D34: sheets
B35: Square feet per pack | C35: =$C$6*Assumptions!$C$19 -> 1000 | D35: sq ft | E35: Print on the front of the pack - it is the honest unit.
B36: DELIVERED COST PER 100 SHEETS | C36: =IFERROR($C$31/($C$34/100),0) -> 0.25682586 | D36: $/100 sh | E36: Compare directly against the Benchmark tab. Market floor is ~$0.18.
B38: E. MARGIN
B39: Revenue per pack | C39: =Assumptions!$C$63*$C$34/100 -> 28.8 | D39: $
B40: Payment processing | C40: =$C$39*Assumptions!$C$64+Assumptions!$C$65 -> 1.1352 | D40: $
B41: Gross profit per pack | C41: =$C$39-$C$31-$C$40 -> 4.5504723 | D41: $
B42: GROSS MARGIN | C42: =IFERROR($C$41/$C$39,0) -> 0.15800251 | D42: % | E42: Below ~25% this product cannot fund customer acquisition. If you are under, the levers are: bigger pack, compression, dual-coast 3PL.
B43: Break-even retail per 100 sheets | C43: =IFERROR(($C$31+$C$40)/($C$34/100),0) -> 0.2694392 | D43: $/100 sh

Sheet Scenario - Pack x Zone
A1: SCENARIO: ROLLS PER PACK x PARCEL ZONE
A2: The core answer. Rows = pack size. Columns = zone. Two output blocks: delivered cost per 100 sheets, and gross margin at your target retail price.
G3: DELIVERED COST PER 100 SHEETS | O3: GROSS MARGIN % AT TARGET RETAIL
A4: Rolls/pack | B4: Actual lb | C4: Cube cu in | D4: DIM lb | E4: Billed lb | F4: Pre-freight $ | G4: 2 | H4: 3 | I4: 4 | J4: 5 | K4: 6 | L4: 7 | M4: 8 | O4: 2 | P4: 3 | Q4: 4 | R4: 5 | S4: 6 | T4: 7 | U4: 8
A5: 6 | B5: =$A5*Assumptions!$C$18+Assumptions!$C$34 -> 1.8131101 | C5: =$A5*Assumptions!$C$36*(1-Assumptions!$C$33) -> 340.2 | D5: =C5/Assumptions!$C$35 -> 2.447482 | E5: =MAX(B5,D5) -> 2.447482 | F5: =$A5*(Assumptions!$C$29+Assumptions!$C$51+Assumptions!$C$52+Assumptions!$C$60)+Assumptions!$C$56+Assumptions!$C$57 -> 5.0428655 | G5: =IFERROR(($F5+IFERROR(INDEX('Freight Rates'!$B$5:$H$13,MATCH($E5,'Freight Rates'!$A$5:$A$13,1),MATCH(G$4,'Freight Rates'!$B$4:$H$4,0)),0))/(($A5*Assumptions!$C$8)/100),0) -> 0.73571475 | H5: =IFERROR(($F5+IFERROR(INDEX('Freight Rates'!$B$5:$H$13,MATCH($E5,'Freight Rates'!$A$5:$A$13,1),MATCH(H$4,'Freight Rates'!$B$4:$H$4,0)),0))/(($A5*Assumptions!$C$8)/100),0) -> 0.7551592 | I5: =IFERROR(($F5+IFERROR(INDEX('Freight Rates'!$B$5:$H$13,MATCH($E5,'Freight Rates'!$A$5:$A$13,1),MATCH(I$4,'Freight Rates'!$B$4:$H$4,0)),0))/(($A5*Assumptions!$C$8)/100),0) -> 0.78293697 | J5: =IFERROR(($F5+IFERROR(INDEX('Freight Rates'!$B$5:$H$13,MATCH($E5,'Freight Rates'!$A$5:$A$13,1),MATCH(J$4,'Freight Rates'!$B$4:$H$4,0)),0))/(($A5*Assumptions!$C$8)/100),0) -> 0.81349253 | K5: =IFERROR(($F5+IFERROR(INDEX('Freight Rates'!$B$5:$H$13,MATCH($E5,'Freight Rates'!$A$5:$A$13,1),MATCH(K$4,'Freight Rates'!$B$4:$H$4,0)),0))/(($A5*Assumptions!$C$8)/100),0) -> 0.84682586 | L5: =IFERROR(($F5+IFERROR(INDEX('Freight Rates'!$B$5:$H$13,MATCH($E5,'Freight Rates'!$A$5:$A$13,1),MATCH(L$4,'Freight Rates'!$B$4:$H$4,0)),0))/(($A5*Assumptions!$C$8)/100),0) -> 0.88293697 | M5: =IFERROR(($F5+IFERROR(INDEX('Freight Rates'!$B$5:$H$13,MATCH($E5,'Freight Rates'!$A$5:$A$13,1),MATCH(M$4,'Freight Rates'!$B$4:$H$4,0)),0))/(($A5*Assumptions!$C$8)/100),0) -> 0.91904809 | O5: =IFERROR(((Assumptions!$C$63*($A5*Assumptions!$C$8)/100)-($F5+IFERROR(INDEX('Freight Rates'!$B$5:$H$13,MATCH($E5,'Freight Rates'!$A$5:$A$13,1),MATCH(O$4,'Freight Rates'!$B$4:$H$4,0)),0))-((Assumptions!$C$63*($A5*Assumptions!$C$8)/100)*Assumptions!$C$64+Assumptions!$C$65))/(Assumptions!$C$63*($A5*Assumptions!$C$8)/100),0) -> -1.3801919 | P5: =IFERROR(((Assumptions!$C$63*($A5*Assumptions!$C$8)/100)-($F5+IFERROR(INDEX('Freight Rates'!$B$5:$H$13,MATCH($E5,'Freight Rates'!$A$5:$A$13,1),MATCH(P$4,'Freight Rates'!$B$4:$H$4,0)),0))-((Assumptions!$C$63*($A5*Assumptions!$C$8)/100)*Assumptions!$C$64+Assumptions!$C$65))/(Assumptions!$C$63*($A5*Assumptions!$C$8)/100),0) -> -1.4409558 | Q5: =IFERROR(((Assumptions!$C$63*($A5*Assumptions!$C$8)/100)-($F5+IFERROR(INDEX('Freight Rates'!$B$5:$H$13,MATCH($E5,'Freight Rates'!$A$5:$A$13,1),MATCH(Q$4,'Freight Rates'!$B$4:$H$4,0)),0))-((Assumptions!$C$63*($A5*Assumptions!$C$8)/100)*Assumptions!$C$64+Assumptions!$C$65))/(Assumptions!$C$63*($A5*Assumptions!$C$8)/100),0) -> -1.5277614 | R5: =IFERROR(((Assumptions!$C$63*($A5*Assumptions!$C$8)/100)-($F5+IFERROR(INDEX('Freight Rates'!$B$5:$H$13,MATCH($E5,'Freight Rates'!$A$5:$A$13,1),MATCH(R$4,'Freight Rates'!$B$4:$H$4,0)),0))-((Assumptions!$C$63*($A5*Assumptions!$C$8)/100)*Assumptions!$C$64+Assumptions!$C$65))/(Assumptions!$C$63*($A5*Assumptions!$C$8)/100),0) -> -1.6232475 | S5: =IFERROR(((Assumptions!$C$63*($A5*Assumptions!$C$8)/100)-($F5+IFERROR(INDEX('Freight Rates'!$B$5:$H$13,MATCH($E5,'Freight Rates'!$A$5:$A$13,1),MATCH(S$4,'Freight Rates'!$B$4:$H$4,0)),0))-((Assumptions!$C$63*($A5*Assumptions!$C$8)/100)*Assumptions!$C$64+Assumptions!$C$65))/(Assumptions!$C$63*($A5*Assumptions!$C$8)/100),0) -> -1.7274142 | T5: =IFERROR(((Assumptions!$C$63*($A5*Assumptions!$C$8)/100)-($F5+IFERROR(INDEX('Freight Rates'!$B$5:$H$13,MATCH($E5,'Freight Rates'!$A$5:$A$13,1),MATCH(T$4,'Freight Rates'!$B$4:$H$4,0)),0))-((Assumptions!$C$63*($A5*Assumptions!$C$8)/100)*Assumptions!$C$64+Assumptions!$C$65))/(Assumptions!$C$63*($A5*Assumptions!$C$8)/100),0) -> -1.8402614 | U5: =IFERROR(((Assumptions!$C$63*($A5*Assumptions!$C$8)/100)-($F5+IFERROR(INDEX('Freight Rates'!$B$5:$H$13,MATCH($E5,'Freight Rates'!$A$5:$A$13,1),MATCH(U$4,'Freight Rates'!$B$4:$H$4,0)),0))-((Assumptions!$C$63*($A5*Assumptions!$C$8)/100)*Assumptions!$C$64+Assumptions!$C$65))/(Assumptions!$C$63*($A5*Assumptions!$C$8)/100),0) -> -1.9531086
A6: 12 | B6: =$A6*Assumptions!$C$18+Assumptions!$C$34 -> 3.0262201 | C6: =$A6*Assumptions!$C$36*(1-Assumptions!$C$33) -> 680.4 | D6: =C6/Assumptions!$C$35 -> 4.894964 | E6: =MAX(B6,D6) -> 4.894964 | F6: =$A6*(Assumptions!$C$29+Assumptions!$C$51+Assumptions!$C$52+Assumptions!$C$60)+Assumptions!$C$56+Assumptions!$C$57 -> 6.4857311 | G6: =IFERROR(($F6+IFERROR(INDEX('Freight Rates'!$B$5:$H$13,MATCH($E6,'Freight Rates'!$A$5:$A$13,1),MATCH(G$4,'Freight Rates'!$B$4:$H$4,0)),0))/(($A6*Assumptions!$C$8)/100),0) -> 0.4176592 | H6: =IFERROR(($F6+IFERROR(INDEX('Freight Rates'!$B$5:$H$13,MATCH($E6,'Freight Rates'!$A$5:$A$13,1),MATCH(H$4,'Freight Rates'!$B$4:$H$4,0)),0))/(($A6*Assumptions!$C$8)/100),0) -> 0.42877031 | I6: =IFERROR(($F6+IFERROR(INDEX('Freight Rates'!$B$5:$H$13,MATCH($E6,'Freight Rates'!$A$5:$A$13,1),MATCH(I$4,'Freight Rates'!$B$4:$H$4,0)),0))/(($A6*Assumptions!$C$8)/100),0) -> 0.44404809 | J6: =IFERROR(($F6+IFERROR(INDEX('Freight Rates'!$B$5:$H$13,MATCH($E6,'Freight Rates'!$A$5:$A$13,1),MATCH(J$4,'Freight Rates'!$B$4:$H$4,0)),0))/(($A6*Assumptions!$C$8)/100),0) -> 0.46071475 | K6: =IFERROR(($F6+IFERROR(INDEX('Freight Rates'!$B$5:$H$13,MATCH($E6,'Freight Rates'!$A$5:$A$13,1),MATCH(K$4,'Freight Rates'!$B$4:$H$4,0)),0))/(($A6*Assumptions!$C$8)/100),0) -> 0.47877031 | L6: =IFERROR(($F6+IFERROR(INDEX('Freight Rates'!$B$5:$H$13,MATCH($E6,'Freight Rates'!$A$5:$A$13,1),MATCH(L$4,'Freight Rates'!$B$4:$H$4,0)),0))/(($A6*Assumptions!$C$8)/100),0) -> 0.49821475 | M6: =IFERROR(($F6+IFERROR(INDEX('Freight Rates'!$B$5:$H$13,MATCH($E6,'Freight Rates'!$A$5:$A$13,1),MATCH(M$4,'Freight Rates'!$B$4:$H$4,0)),0))/(($A6*Assumptions!$C$8)/100),0) -> 0.51904809 | O6: =IFERROR(((Assumptions!$C$63*($A6*Assumptions!$C$8)/100)-($F6+IFERROR(INDEX('Freight Rates'!$B$5:$H$13,MATCH($E6,'Freight Rates'!$A$5:$A$13,1),MATCH(O$4,'Freight Rates'!$B$4:$H$4,0)),0))-((Assumptions!$C$63*($A6*Assumptions!$C$8)/100)*Assumptions!$C$64+Assumptions!$C$65))/(Assumptions!$C$63*($A6*Assumptions!$C$8)/100),0) -> -0.36022666 | P6: =IFERROR(((Assumptions!$C$63*($A6*Assumptions!$C$8)/100)-($F6+IFERROR(INDEX('Freight Rates'!$B$5:$H$13,MATCH($E6,'Freight Rates'!$A$5:$A$13,1),MATCH(P$4,'Freight Rates'!$B$4:$H$4,0)),0))-((Assumptions!$C$63*($A6*Assumptions!$C$8)/100)*Assumptions!$C$64+Assumptions!$C$65))/(Assumptions!$C$63*($A6*Assumptions!$C$8)/100),0) -> -0.39494888 | Q6: =IFERROR(((Assumptions!$C$63*($A6*Assumptions!$C$8)/100)-($F6+IFERROR(INDEX('Freight Rates'!$B$5:$H$13,MATCH($E6,'Freight Rates'!$A$5:$A$13,1),MATCH(Q$4,'Freight Rates'!$B$4:$H$4,0)),0))-((Assumptions!$C$63*($A6*Assumptions!$C$8)/100)*Assumptions!$C$64+Assumptions!$C$65))/(Assumptions!$C$63*($A6*Assumptions!$C$8)/100),0) -> -0.44269193 | R6: =IFERROR(((Assumptions!$C$63*($A6*Assumptions!$C$8)/100)-($F6+IFERROR(INDEX('Freight Rates'!$B$5:$H$13,MATCH($E6,'Freight Rates'!$A$5:$A$13,1),MATCH(R$4,'Freight Rates'!$B$4:$H$4,0)),0))-((Assumptions!$C$63*($A6*Assumptions!$C$8)/100)*Assumptions!$C$64+Assumptions!$C$65))/(Assumptions!$C$63*($A6*Assumptions!$C$8)/100),0) -> -0.49477527 | S6: =IFERROR(((Assumptions!$C$63*($A6*Assumptions!$C$8)/100)-($F6+IFERROR(INDEX('Freight Rates'!$B$5:$H$13,MATCH($E6,'Freight Rates'!$A$5:$A$13,1),MATCH(S$4,'Freight Rates'!$B$4:$H$4,0)),0))-((Assumptions!$C$63*($A6*Assumptions!$C$8)/100)*Assumptions!$C$64+Assumptions!$C$65))/(Assumptions!$C$63*($A6*Assumptions!$C$8)/100),0) -> -0.55119888 | T6: =IFERROR(((Assumptions!$C$63*($A6*Assumptions!$C$8)/100)-($F6+IFERROR(INDEX('Freight Rates'!$B$5:$H$13,MATCH($E6,'Freight Rates'!$A$5:$A$13,1),MATCH(T$4,'Freight Rates'!$B$4:$H$4,0)),0))-((Assumptions!$C$63*($A6*Assumptions!$C$8)/100)*Assumptions!$C$64+Assumptions!$C$65))/(Assumptions!$C$63*($A6*Assumptions!$C$8)/100),0) -> -0.61196277 | U6: =IFERROR(((Assumptions!$C$63*($A6*Assumptions!$C$8)/100)-($F6+IFERROR(INDEX('Freight Rates'!$B$5:$H$13,MATCH($E6,'Freight Rates'!$A$5:$A$13,1),MATCH(U$4,'Freight Rates'!$B$4:$H$4,0)),0))-((Assumptions!$C$63*($A6*Assumptions!$C$8)/100)*Assumptions!$C$64+Assumptions!$C$65))/(Assumptions!$C$63*($A6*Assumptions!$C$8)/100),0) -> -0.67706693
A7: 18 | B7: =$A7*Assumptions!$C$18+Assumptions!$C$34 -> 4.2393302 | C7: =$A7*Assumptions!$C$36*(1-Assumptions!$C$33) -> 1020.6 | D7: =C7/Assumptions!$C$35 -> 7.342446 | E7: =MAX(B7,D7) -> 7.342446 | F7: =$A7*(Assumptions!$C$29+Assumptions!$C$51+Assumptions!$C$52+Assumptions!$C$60)+Assumptions!$C$56+Assumptions!$C$57 -> 7.9285966 | G7: =IFERROR(($F7+IFERROR(INDEX('Freight Rates'!$B$5:$H$13,MATCH($E7,'Freight Rates'!$A$5:$A$13,1),MATCH(G$4,'Freight Rates'!$B$4:$H$4,0)),0))/(($A7*Assumptions!$C$8)/100),0) -> 0.31164068 | H7: =IFERROR(($F7+IFERROR(INDEX('Freight Rates'!$B$5:$H$13,MATCH($E7,'Freight Rates'!$A$5:$A$13,1),MATCH(H$4,'Freight Rates'!$B$4:$H$4,0)),0))/(($A7*Assumptions!$C$8)/100),0) -> 0.31904809 | I7: =IFERROR(($F7+IFERROR(INDEX('Freight Rates'!$B$5:$H$13,MATCH($E7,'Freight Rates'!$A$5:$A$13,1),MATCH(I$4,'Freight Rates'!$B$4:$H$4,0)),0))/(($A7*Assumptions!$C$8)/100),0) -> 0.3301592 | J7: =IFERROR(($F7+IFERROR(INDEX('Freight Rates'!$B$5:$H$13,MATCH($E7,'Freight Rates'!$A$5:$A$13,1),MATCH(J$4,'Freight Rates'!$B$4:$H$4,0)),0))/(($A7*Assumptions!$C$8)/100),0) -> 0.34312216 | K7: =IFERROR(($F7+IFERROR(INDEX('Freight Rates'!$B$5:$H$13,MATCH($E7,'Freight Rates'!$A$5:$A$13,1),MATCH(K$4,'Freight Rates'!$B$4:$H$4,0)),0))/(($A7*Assumptions!$C$8)/100),0) -> 0.35608512 | L7: =IFERROR(($F7+IFERROR(INDEX('Freight Rates'!$B$5:$H$13,MATCH($E7,'Freight Rates'!$A$5:$A$13,1),MATCH(L$4,'Freight Rates'!$B$4:$H$4,0)),0))/(($A7*Assumptions!$C$8)/100),0) -> 0.37089994 | M7: =IFERROR(($F7+IFERROR(INDEX('Freight Rates'!$B$5:$H$13,MATCH($E7,'Freight Rates'!$A$5:$A$13,1),MATCH(M$4,'Freight Rates'!$B$4:$H$4,0)),0))/(($A7*Assumptions!$C$8)/100),0) -> 0.38571475 | O7: =IFERROR(((Assumptions!$C$63*($A7*Assumptions!$C$8)/100)-($F7+IFERROR(INDEX('Freight Rates'!$B$5:$H$13,MATCH($E7,'Freight Rates'!$A$5:$A$13,1),MATCH(O$4,'Freight Rates'!$B$4:$H$4,0)),0))-((Assumptions!$C$63*($A7*Assumptions!$C$8)/100)*Assumptions!$C$64+Assumptions!$C$65))/(Assumptions!$C$63*($A7*Assumptions!$C$8)/100),0) -> -0.020238229 | P7: =IFERROR(((Assumptions!$C$63*($A7*Assumptions!$C$8)/100)-($F7+IFERROR(INDEX('Freight Rates'!$B$5:$H$13,MATCH($E7,'Freight Rates'!$A$5:$A$13,1),MATCH(P$4,'Freight Rates'!$B$4:$H$4,0)),0))-((Assumptions!$C$63*($A7*Assumptions!$C$8)/100)*Assumptions!$C$64+Assumptions!$C$65))/(Assumptions!$C$63*($A7*Assumptions!$C$8)/100),0) -> -0.043386377 | Q7: =IFERROR(((Assumptions!$C$63*($A7*Assumptions!$C$8)/100)-($F7+IFERROR(INDEX('Freight Rates'!$B$5:$H$13,MATCH($E7,'Freight Rates'!$A$5:$A$13,1),MATCH(Q$4,'Freight Rates'!$B$4:$H$4,0)),0))-((Assumptions!$C$63*($A7*Assumptions!$C$8)/100)*Assumptions!$C$64+Assumptions!$C$65))/(Assumptions!$C$63*($A7*Assumptions!$C$8)/100),0) -> -0.0781086 | R7: =IFERROR(((Assumptions!$C$63*($A7*Assumptions!$C$8)/100)-($F7+IFERROR(INDEX('Freight Rates'!$B$5:$H$13,MATCH($E7,'Freight Rates'!$A$5:$A$13,1),MATCH(R$4,'Freight Rates'!$B$4:$H$4,0)),0))-((Assumptions!$C$63*($A7*Assumptions!$C$8)/100)*Assumptions!$C$64+Assumptions!$C$65))/(Assumptions!$C$63*($A7*Assumptions!$C$8)/100),0) -> -0.11861786 | S7: =IFERROR(((Assumptions!$C$63*($A7*Assumptions!$C$8)/100)-($F7+IFERROR(INDEX('Freight Rates'!$B$5:$H$13,MATCH($E7,'Freight Rates'!$A$5:$A$13,1),MATCH(S$4,'Freight Rates'!$B$4:$H$4,0)),0))-((Assumptions!$C$63*($A7*Assumptions!$C$8)/100)*Assumptions!$C$64+Assumptions!$C$65))/(Assumptions!$C$63*($A7*Assumptions!$C$8)/100),0) -> -0.15912712 | T7: =IFERROR(((Assumptions!$C$63*($A7*Assumptions!$C$8)/100)-($F7+IFERROR(INDEX('Freight Rates'!$B$5:$H$13,MATCH($E7,'Freight Rates'!$A$5:$A$13,1),MATCH(T$4,'Freight Rates'!$B$4:$H$4,0)),0))-((Assumptions!$C$63*($A7*Assumptions!$C$8)/100)*Assumptions!$C$64+Assumptions!$C$65))/(Assumptions!$C$63*($A7*Assumptions!$C$8)/100),0) -> -0.20542341 | U7: =IFERROR(((Assumptions!$C$63*($A7*Assumptions!$C$8)/100)-($F7+IFERROR(INDEX('Freight Rates'!$B$5:$H$13,MATCH($E7,'Freight Rates'!$A$5:$A$13,1),MATCH(U$4,'Freight Rates'!$B$4:$H$4,0)),0))-((Assumptions!$C$63*($A7*Assumptions!$C$8)/100)*Assumptions!$C$64+Assumptions!$C$65))/(Assumptions!$C$63*($A7*Assumptions!$C$8)/100),0) -> -0.25171971
A8: 24 | B8: =$A8*Assumptions!$C$18+Assumptions!$C$34 -> 5.4524403 | C8: =$A8*Assumptions!$C$36*(1-Assumptions!$C$33) -> 1360.8 | D8: =C8/Assumptions!$C$35 -> 9.7899281 | E8: =MAX(B8,D8) -> 9.7899281 | F8: =$A8*(Assumptions!$C$29+Assumptions!$C$51+Assumptions!$C$52+Assumptions!$C$60)+Assumptions!$C$56+Assumptions!$C$57 -> 9.3714621 | G8: =IFERROR(($F8+IFERROR(INDEX('Freight Rates'!$B$5:$H$13,MATCH($E8,'Freight Rates'!$A$5:$A$13,1),MATCH(G$4,'Freight Rates'!$B$4:$H$4,0)),0))/(($A8*Assumptions!$C$8)/100),0) -> 0.25377031 | H8: =IFERROR(($F8+IFERROR(INDEX('Freight Rates'!$B$5:$H$13,MATCH($E8,'Freight Rates'!$A$5:$A$13,1),MATCH(H$4,'Freight Rates'!$B$4:$H$4,0)),0))/(($A8*Assumptions!$C$8)/100),0) -> 0.25932586 | I8: =IFERROR(($F8+IFERROR(INDEX('Freight Rates'!$B$5:$H$13,MATCH($E8,'Freight Rates'!$A$5:$A$13,1),MATCH(I$4,'Freight Rates'!$B$4:$H$4,0)),0))/(($A8*Assumptions!$C$8)/100),0) -> 0.2676592 | J8: =IFERROR(($F8+IFERROR(INDEX('Freight Rates'!$B$5:$H$13,MATCH($E8,'Freight Rates'!$A$5:$A$13,1),MATCH(J$4,'Freight Rates'!$B$4:$H$4,0)),0))/(($A8*Assumptions!$C$8)/100),0) -> 0.27738142 | K8: =IFERROR(($F8+IFERROR(INDEX('Freight Rates'!$B$5:$H$13,MATCH($E8,'Freight Rates'!$A$5:$A$13,1),MATCH(K$4,'Freight Rates'!$B$4:$H$4,0)),0))/(($A8*Assumptions!$C$8)/100),0) -> 0.28710364 | L8: =IFERROR(($F8+IFERROR(INDEX('Freight Rates'!$B$5:$H$13,MATCH($E8,'Freight Rates'!$A$5:$A$13,1),MATCH(L$4,'Freight Rates'!$B$4:$H$4,0)),0))/(($A8*Assumptions!$C$8)/100),0) -> 0.29821475 | M8: =IFERROR(($F8+IFERROR(INDEX('Freight Rates'!$B$5:$H$13,MATCH($E8,'Freight Rates'!$A$5:$A$13,1),MATCH(M$4,'Freight Rates'!$B$4:$H$4,0)),0))/(($A8*Assumptions!$C$8)/100),0) -> 0.30932586 | O8: =IFERROR(((Assumptions!$C$63*($A8*Assumptions!$C$8)/100)-($F8+IFERROR(INDEX('Freight Rates'!$B$5:$H$13,MATCH($E8,'Freight Rates'!$A$5:$A$13,1),MATCH(O$4,'Freight Rates'!$B$4:$H$4,0)),0))-((Assumptions!$C$63*($A8*Assumptions!$C$8)/100)*Assumptions!$C$64+Assumptions!$C$65))/(Assumptions!$C$63*($A8*Assumptions!$C$8)/100),0) -> 0.16494696 | P8: =IFERROR(((Assumptions!$C$63*($A8*Assumptions!$C$8)/100)-($F8+IFERROR(INDEX('Freight Rates'!$B$5:$H$13,MATCH($E8,'Freight Rates'!$A$5:$A$13,1),MATCH(P$4,'Freight Rates'!$B$4:$H$4,0)),0))-((Assumptions!$C$63*($A8*Assumptions!$C$8)/100)*Assumptions!$C$64+Assumptions!$C$65))/(Assumptions!$C$63*($A8*Assumptions!$C$8)/100),0) -> 0.14758584 | Q8: =IFERROR(((Assumptions!$C$63*($A8*Assumptions!$C$8)/100)-($F8+IFERROR(INDEX('Freight Rates'!$B$5:$H$13,MATCH($E8,'Freight Rates'!$A$5:$A$13,1),MATCH(Q$4,'Freight Rates'!$B$4:$H$4,0)),0))-((Assumptions!$C$63*($A8*Assumptions!$C$8)/100)*Assumptions!$C$64+Assumptions!$C$65))/(Assumptions!$C$63*($A8*Assumptions!$C$8)/100),0) -> 0.12154418 | R8: =IFERROR(((Assumptions!$C$63*($A8*Assumptions!$C$8)/100)-($F8+IFERROR(INDEX('Freight Rates'!$B$5:$H$13,MATCH($E8,'Freight Rates'!$A$5:$A$13,1),MATCH(R$4,'Freight Rates'!$B$4:$H$4,0)),0))-((Assumptions!$C$63*($A8*Assumptions!$C$8)/100)*Assumptions!$C$64+Assumptions!$C$65))/(Assumptions!$C$63*($A8*Assumptions!$C$8)/100),0) -> 0.091162234 | S8: =IFERROR(((Assumptions!$C$63*($A8*Assumptions!$C$8)/100)-($F8+IFERROR(INDEX('Freight Rates'!$B$5:$H$13,MATCH($E8,'Freight Rates'!$A$5:$A$13,1),MATCH(S$4,'Freight Rates'!$B$4:$H$4,0)),0))-((Assumptions!$C$63*($A8*Assumptions!$C$8)/100)*Assumptions!$C$64+Assumptions!$C$65))/(Assumptions!$C$63*($A8*Assumptions!$C$8)/100),0) -> 0.060780289 | T8: =IFERROR(((Assumptions!$C$63*($A8*Assumptions!$C$8)/100)-($F8+IFERROR(INDEX('Freight Rates'!$B$5:$H$13,MATCH($E8,'Freight Rates'!$A$5:$A$13,1),MATCH(T$4,'Freight Rates'!$B$4:$H$4,0)),0))-((Assumptions!$C$63*($A8*Assumptions!$C$8)/100)*Assumptions!$C$64+Assumptions!$C$65))/(Assumptions!$C$63*($A8*Assumptions!$C$8)/100),0) -> 0.026058067 | U8: =IFERROR(((Assumptions!$C$63*($A8*Assumptions!$C$8)/100)-($F8+IFERROR(INDEX('Freight Rates'!$B$5:$H$13,MATCH($E8,'Freight Rates'!$A$5:$A$13,1),MATCH(U$4,'Freight Rates'!$B$4:$H$4,0)),0))-((Assumptions!$C$63*($A8*Assumptions!$C$8)/100)*Assumptions!$C$64+Assumptions!$C$65))/(Assumptions!$C$63*($A8*Assumptions!$C$8)/100),0) -> -0.0086641551
A9: 30 | B9: =$A9*Assumptions!$C$18+Assumptions!$C$34 -> 6.6655504 | C9: =$A9*Assumptions!$C$36*(1-Assumptions!$C$33) -> 1701 | D9: =C9/Assumptions!$C$35 -> 12.23741 | E9: =MAX(B9,D9) -> 12.23741 | F9: =$A9*(Assumptions!$C$29+Assumptions!$C$51+Assumptions!$C$52+Assumptions!$C$60)+Assumptions!$C$56+Assumptions!$C$57 -> 10.814328 | G9: =IFERROR(($F9+IFERROR(INDEX('Freight Rates'!$B$5:$H$13,MATCH($E9,'Freight Rates'!$A$5:$A$13,1),MATCH(G$4,'Freight Rates'!$B$4:$H$4,0)),0))/(($A9*Assumptions!$C$8)/100),0) -> 0.22904809 | H9: =IFERROR(($F9+IFERROR(INDEX('Freight Rates'!$B$5:$H$13,MATCH($E9,'Freight Rates'!$A$5:$A$13,1),MATCH(H$4,'Freight Rates'!$B$4:$H$4,0)),0))/(($A9*Assumptions!$C$8)/100),0) -> 0.23571475 | I9: =IFERROR(($F9+IFERROR(INDEX('Freight Rates'!$B$5:$H$13,MATCH($E9,'Freight Rates'!$A$5:$A$13,1),MATCH(I$4,'Freight Rates'!$B$4:$H$4,0)),0))/(($A9*Assumptions!$C$8)/100),0) -> 0.24571475 | J9: =IFERROR(($F9+IFERROR(INDEX('Freight Rates'!$B$5:$H$13,MATCH($E9,'Freight Rates'!$A$5:$A$13,1),MATCH(J$4,'Freight Rates'!$B$4:$H$4,0)),0))/(($A9*Assumptions!$C$8)/100),0) -> 0.25682586 | K9: =IFERROR(($F9+IFERROR(INDEX('Freight Rates'!$B$5:$H$13,MATCH($E9,'Freight Rates'!$A$5:$A$13,1),MATCH(K$4,'Freight Rates'!$B$4:$H$4,0)),0))/(($A9*Assumptions!$C$8)/100),0) -> 0.26793697 | L9: =IFERROR(($F9+IFERROR(INDEX('Freight Rates'!$B$5:$H$13,MATCH($E9,'Freight Rates'!$A$5:$A$13,1),MATCH(L$4,'Freight Rates'!$B$4:$H$4,0)),0))/(($A9*Assumptions!$C$8)/100),0) -> 0.2801592 | M9: =IFERROR(($F9+IFERROR(INDEX('Freight Rates'!$B$5:$H$13,MATCH($E9,'Freight Rates'!$A$5:$A$13,1),MATCH(M$4,'Freight Rates'!$B$4:$H$4,0)),0))/(($A9*Assumptions!$C$8)/100),0) -> 0.29238142 | O9: =IFERROR(((Assumptions!$C$63*($A9*Assumptions!$C$8)/100)-($F9+IFERROR(INDEX('Freight Rates'!$B$5:$H$13,MATCH($E9,'Freight Rates'!$A$5:$A$13,1),MATCH(O$4,'Freight Rates'!$B$4:$H$4,0)),0))-((Assumptions!$C$63*($A9*Assumptions!$C$8)/100)*Assumptions!$C$64+Assumptions!$C$65))/(Assumptions!$C$63*($A9*Assumptions!$C$8)/100),0) -> 0.24480807 | P9: =IFERROR(((Assumptions!$C$63*($A9*Assumptions!$C$8)/100)-($F9+IFERROR(INDEX('Freight Rates'!$B$5:$H$13,MATCH($E9,'Freight Rates'!$A$5:$A$13,1),MATCH(P$4,'Freight Rates'!$B$4:$H$4,0)),0))-((Assumptions!$C$63*($A9*Assumptions!$C$8)/100)*Assumptions!$C$64+Assumptions!$C$65))/(Assumptions!$C$63*($A9*Assumptions!$C$8)/100),0) -> 0.22397473 | Q9: =IFERROR(((Assumptions!$C$63*($A9*Assumptions!$C$8)/100)-($F9+IFERROR(INDEX('Freight Rates'!$B$5:$H$13,MATCH($E9,'Freight Rates'!$A$5:$A$13,1),MATCH(Q$4,'Freight Rates'!$B$4:$H$4,0)),0))-((Assumptions!$C$63*($A9*Assumptions!$C$8)/100)*Assumptions!$C$64+Assumptions!$C$65))/(Assumptions!$C$63*($A9*Assumptions!$C$8)/100),0) -> 0.19272473 | R9: =IFERROR(((Assumptions!$C$63*($A9*Assumptions!$C$8)/100)-($F9+IFERROR(INDEX('Freight Rates'!$B$5:$H$13,MATCH($E9,'Freight Rates'!$A$5:$A$13,1),MATCH(R$4,'Freight Rates'!$B$4:$H$4,0)),0))-((Assumptions!$C$63*($A9*Assumptions!$C$8)/100)*Assumptions!$C$64+Assumptions!$C$65))/(Assumptions!$C$63*($A9*Assumptions!$C$8)/100),0) -> 0.15800251 | S9: =IFERROR(((Assumptions!$C$63*($A9*Assumptions!$C$8)/100)-($F9+IFERROR(INDEX('Freight Rates'!$B$5:$H$13,MATCH($E9,'Freight Rates'!$A$5:$A$13,1),MATCH(S$4,'Freight Rates'!$B$4:$H$4,0)),0))-((Assumptions!$C$63*($A9*Assumptions!$C$8)/100)*Assumptions!$C$64+Assumptions!$C$65))/(Assumptions!$C$63*($A9*Assumptions!$C$8)/100),0) -> 0.12328029 | T9: =IFERROR(((Assumptions!$C$63*($A9*Assumptions!$C$8)/100)-($F9+IFERROR(INDEX('Freight Rates'!$B$5:$H$13,MATCH($E9,'Freight Rates'!$A$5:$A$13,1),MATCH(T$4,'Freight Rates'!$B$4:$H$4,0)),0))-((Assumptions!$C$63*($A9*Assumptions!$C$8)/100)*Assumptions!$C$64+Assumptions!$C$65))/(Assumptions!$C$63*($A9*Assumptions!$C$8)/100),0) -> 0.085085845 | U9: =IFERROR(((Assumptions!$C$63*($A9*Assumptions!$C$8)/100)-($F9+IFERROR(INDEX('Freight Rates'!$B$5:$H$13,MATCH($E9,'Freight Rates'!$A$5:$A$13,1),MATCH(U$4,'Freight Rates'!$B$4:$H$4,0)),0))-((Assumptions!$C$63*($A9*Assumptions!$C$8)/100)*Assumptions!$C$64+Assumptions!$C$65))/(Assumptions!$C$63*($A9*Assumptions!$C$8)/100),0) -> 0.0468914
A10: 36 | B10: =$A10*Assumptions!$C$18+Assumptions!$C$34 -> 7.8786604 | C10: =$A10*Assumptions!$C$36*(1-Assumptions!$C$33) -> 2041.2 | D10: =C10/Assumptions!$C$35 -> 14.684892 | E10: =MAX(B10,D10) -> 14.684892 | F10: =$A10*(Assumptions!$C$29+Assumptions!$C$51+Assumptions!$C$52+Assumptions!$C$60)+Assumptions!$C$56+Assumptions!$C$57 -> 12.257193 | G10: =IFERROR(($F10+IFERROR(INDEX('Freight Rates'!$B$5:$H$13,MATCH($E10,'Freight Rates'!$A$5:$A$13,1),MATCH(G$4,'Freight Rates'!$B$4:$H$4,0)),0))/(($A10*Assumptions!$C$8)/100),0) -> 0.20423327 | H10: =IFERROR(($F10+IFERROR(INDEX('Freight Rates'!$B$5:$H$13,MATCH($E10,'Freight Rates'!$A$5:$A$13,1),MATCH(H$4,'Freight Rates'!$B$4:$H$4,0)),0))/(($A10*Assumptions!$C$8)/100),0) -> 0.20978883 | I10: =IFERROR(($F10+IFERROR(INDEX('Freight Rates'!$B$5:$H$13,MATCH($E10,'Freight Rates'!$A$5:$A$13,1),MATCH(I$4,'Freight Rates'!$B$4:$H$4,0)),0))/(($A10*Assumptions!$C$8)/100),0) -> 0.21812216 | J10: =IFERROR(($F10+IFERROR(INDEX('Freight Rates'!$B$5:$H$13,MATCH($E10,'Freight Rates'!$A$5:$A$13,1),MATCH(J$4,'Freight Rates'!$B$4:$H$4,0)),0))/(($A10*Assumptions!$C$8)/100),0) -> 0.22738142 | K10: =IFERROR(($F10+IFERROR(INDEX('Freight Rates'!$B$5:$H$13,MATCH($E10,'Freight Rates'!$A$5:$A$13,1),MATCH(K$4,'Freight Rates'!$B$4:$H$4,0)),0))/(($A10*Assumptions!$C$8)/100),0) -> 0.23664068 | L10: =IFERROR(($F10+IFERROR(INDEX('Freight Rates'!$B$5:$H$13,MATCH($E10,'Freight Rates'!$A$5:$A$13,1),MATCH(L$4,'Freight Rates'!$B$4:$H$4,0)),0))/(($A10*Assumptions!$C$8)/100),0) -> 0.24682586 | M10: =IFERROR(($F10+IFERROR(INDEX('Freight Rates'!$B$5:$H$13,MATCH($E10,'Freight Rates'!$A$5:$A$13,1),MATCH(M$4,'Freight Rates'!$B$4:$H$4,0)),0))/(($A10*Assumptions!$C$8)/100),0) -> 0.25701105 | O10: =IFERROR(((Assumptions!$C$63*($A10*Assumptions!$C$8)/100)-($F10+IFERROR(INDEX('Freight Rates'!$B$5:$H$13,MATCH($E10,'Freight Rates'!$A$5:$A$13,1),MATCH(O$4,'Freight Rates'!$B$4:$H$4,0)),0))-((Assumptions!$C$63*($A10*Assumptions!$C$8)/100)*Assumptions!$C$64+Assumptions!$C$65))/(Assumptions!$C$63*($A10*Assumptions!$C$8)/100),0) -> 0.32409047 | P10: =IFERROR(((Assumptions!$C$63*($A10*Assumptions!$C$8)/100)-($F10+IFERROR(INDEX('Freight Rates'!$B$5:$H$13,MATCH($E10,'Freight Rates'!$A$5:$A$13,1),MATCH(P$4,'Freight Rates'!$B$4:$H$4,0)),0))-((Assumptions!$C$63*($A10*Assumptions!$C$8)/100)*Assumptions!$C$64+Assumptions!$C$65))/(Assumptions!$C$63*($A10*Assumptions!$C$8)/100),0) -> 0.30672936 | Q10: =IFERROR(((Assumptions!$C$63*($A10*Assumptions!$C$8)/100)-($F10+IFERROR(INDEX('Freight Rates'!$B$5:$H$13,MATCH($E10,'Freight Rates'!$A$5:$A$13,1),MATCH(Q$4,'Freight Rates'!$B$4:$H$4,0)),0))-((Assumptions!$C$63*($A10*Assumptions!$C$8)/100)*Assumptions!$C$64+Assumptions!$C$65))/(Assumptions!$C$63*($A10*Assumptions!$C$8)/100),0) -> 0.2806877 | R10: =IFERROR(((Assumptions!$C$63*($A10*Assumptions!$C$8)/100)-($F10+IFERROR(INDEX('Freight Rates'!$B$5:$H$13,MATCH($E10,'Freight Rates'!$A$5:$A$13,1),MATCH(R$4,'Freight Rates'!$B$4:$H$4,0)),0))-((Assumptions!$C$63*($A10*Assumptions!$C$8)/100)*Assumptions!$C$64+Assumptions!$C$65))/(Assumptions!$C$63*($A10*Assumptions!$C$8)/100),0) -> 0.25175251 | S10: =IFERROR(((Assumptions!$C$63*($A10*Assumptions!$C$8)/100)-($F10+IFERROR(INDEX('Freight Rates'!$B$5:$H$13,MATCH($E10,'Freight Rates'!$A$5:$A$13,1),MATCH(S$4,'Freight Rates'!$B$4:$H$4,0)),0))-((Assumptions!$C$63*($A10*Assumptions!$C$8)/100)*Assumptions!$C$64+Assumptions!$C$65))/(Assumptions!$C$63*($A10*Assumptions!$C$8)/100),0) -> 0.22281733 | T10: =IFERROR(((Assumptions!$C$63*($A10*Assumptions!$C$8)/100)-($F10+IFERROR(INDEX('Freight Rates'!$B$5:$H$13,MATCH($E10,'Freight Rates'!$A$5:$A$13,1),MATCH(T$4,'Freight Rates'!$B$4:$H$4,0)),0))-((Assumptions!$C$63*($A10*Assumptions!$C$8)/100)*Assumptions!$C$64+Assumptions!$C$65))/(Assumptions!$C$63*($A10*Assumptions!$C$8)/100),0) -> 0.19098862 | U10: =IFERROR(((Assumptions!$C$63*($A10*Assumptions!$C$8)/100)-($F10+IFERROR(INDEX('Freight Rates'!$B$5:$H$13,MATCH($E10,'Freight Rates'!$A$5:$A$13,1),MATCH(U$4,'Freight Rates'!$B$4:$H$4,0)),0))-((Assumptions!$C$63*($A10*Assumptions!$C$8)/100)*Assumptions!$C$64+Assumptions!$C$65))/(Assumptions!$C$63*($A10*Assumptions!$C$8)/100),0) -> 0.15915992
A11: 48 | B11: =$A11*Assumptions!$C$18+Assumptions!$C$34 -> 10.304881 | C11: =$A11*Assumptions!$C$36*(1-Assumptions!$C$33) -> 2721.6 | D11: =C11/Assumptions!$C$35 -> 19.579856 | E11: =MAX(B11,D11) -> 19.579856 | F11: =$A11*(Assumptions!$C$29+Assumptions!$C$51+Assumptions!$C$52+Assumptions!$C$60)+Assumptions!$C$56+Assumptions!$C$57 -> 15.142924 | G11: =IFERROR(($F11+IFERROR(INDEX('Freight Rates'!$B$5:$H$13,MATCH($E11,'Freight Rates'!$A$5:$A$13,1),MATCH(G$4,'Freight Rates'!$B$4:$H$4,0)),0))/(($A11*Assumptions!$C$8)/100),0) -> 0.18085364 | H11: =IFERROR(($F11+IFERROR(INDEX('Freight Rates'!$B$5:$H$13,MATCH($E11,'Freight Rates'!$A$5:$A$13,1),MATCH(H$4,'Freight Rates'!$B$4:$H$4,0)),0))/(($A11*Assumptions!$C$8)/100),0) -> 0.1864092 | I11: =IFERROR(($F11+IFERROR(INDEX('Freight Rates'!$B$5:$H$13,MATCH($E11,'Freight Rates'!$A$5:$A$13,1),MATCH(I$4,'Freight Rates'!$B$4:$H$4,0)),0))/(($A11*Assumptions!$C$8)/100),0) -> 0.19474253 | J11: =IFERROR(($F11+IFERROR(INDEX('Freight Rates'!$B$5:$H$13,MATCH($E11,'Freight Rates'!$A$5:$A$13,1),MATCH(J$4,'Freight Rates'!$B$4:$H$4,0)),0))/(($A11*Assumptions!$C$8)/100),0) -> 0.20377031 | K11: =IFERROR(($F11+IFERROR(INDEX('Freight Rates'!$B$5:$H$13,MATCH($E11,'Freight Rates'!$A$5:$A$13,1),MATCH(K$4,'Freight Rates'!$B$4:$H$4,0)),0))/(($A11*Assumptions!$C$8)/100),0) -> 0.21349253 | L11: =IFERROR(($F11+IFERROR(INDEX('Freight Rates'!$B$5:$H$13,MATCH($E11,'Freight Rates'!$A$5:$A$13,1),MATCH(L$4,'Freight Rates'!$B$4:$H$4,0)),0))/(($A11*Assumptions!$C$8)/100),0) -> 0.22321475 | M11: =IFERROR(($F11+IFERROR(INDEX('Freight Rates'!$B$5:$H$13,MATCH($E11,'Freight Rates'!$A$5:$A$13,1),MATCH(M$4,'Freight Rates'!$B$4:$H$4,0)),0))/(($A11*Assumptions!$C$8)/100),0) -> 0.23363142 | O11: =IFERROR(((Assumptions!$C$63*($A11*Assumptions!$C$8)/100)-($F11+IFERROR(INDEX('Freight Rates'!$B$5:$H$13,MATCH($E11,'Freight Rates'!$A$5:$A$13,1),MATCH(O$4,'Freight Rates'!$B$4:$H$4,0)),0))-((Assumptions!$C$63*($A11*Assumptions!$C$8)/100)*Assumptions!$C$64+Assumptions!$C$65))/(Assumptions!$C$63*($A11*Assumptions!$C$8)/100),0) -> 0.39932196 | P11: =IFERROR(((Assumptions!$C$63*($A11*Assumptions!$C$8)/100)-($F11+IFERROR(INDEX('Freight Rates'!$B$5:$H$13,MATCH($E11,'Freight Rates'!$A$5:$A$13,1),MATCH(P$4,'Freight Rates'!$B$4:$H$4,0)),0))-((Assumptions!$C$63*($A11*Assumptions!$C$8)/100)*Assumptions!$C$64+Assumptions!$C$65))/(Assumptions!$C$63*($A11*Assumptions!$C$8)/100),0) -> 0.38196084 | Q11: =IFERROR(((Assumptions!$C$63*($A11*Assumptions!$C$8)/100)-($F11+IFERROR(INDEX('Freight Rates'!$B$5:$H$13,MATCH($E11,'Freight Rates'!$A$5:$A$13,1),MATCH(Q$4,'Freight Rates'!$B$4:$H$4,0)),0))-((Assumptions!$C$63*($A11*Assumptions!$C$8)/100)*Assumptions!$C$64+Assumptions!$C$65))/(Assumptions!$C$63*($A11*Assumptions!$C$8)/100),0) -> 0.35591918 | R11: =IFERROR(((Assumptions!$C$63*($A11*Assumptions!$C$8)/100)-($F11+IFERROR(INDEX('Freight Rates'!$B$5:$H$13,MATCH($E11,'Freight Rates'!$A$5:$A$13,1),MATCH(R$4,'Freight Rates'!$B$4:$H$4,0)),0))-((Assumptions!$C$63*($A11*Assumptions!$C$8)/100)*Assumptions!$C$64+Assumptions!$C$65))/(Assumptions!$C$63*($A11*Assumptions!$C$8)/100),0) -> 0.32770737 | S11: =IFERROR(((Assumptions!$C$63*($A11*Assumptions!$C$8)/100)-($F11+IFERROR(INDEX('Freight Rates'!$B$5:$H$13,MATCH($E11,'Freight Rates'!$A$5:$A$13,1),MATCH(S$4,'Freight Rates'!$B$4:$H$4,0)),0))-((Assumptions!$C$63*($A11*Assumptions!$C$8)/100)*Assumptions!$C$64+Assumptions!$C$65))/(Assumptions!$C$63*($A11*Assumptions!$C$8)/100),0) -> 0.29732543 | T11: =IFERROR(((Assumptions!$C$63*($A11*Assumptions!$C$8)/100)-($F11+IFERROR(INDEX('Freight Rates'!$B$5:$H$13,MATCH($E11,'Freight Rates'!$A$5:$A$13,1),MATCH(T$4,'Freight Rates'!$B$4:$H$4,0)),0))-((Assumptions!$C$63*($A11*Assumptions!$C$8)/100)*Assumptions!$C$64+Assumptions!$C$65))/(Assumptions!$C$63*($A11*Assumptions!$C$8)/100),0) -> 0.26694348 | U11: =IFERROR(((Assumptions!$C$63*($A11*Assumptions!$C$8)/100)-($F11+IFERROR(INDEX('Freight Rates'!$B$5:$H$13,MATCH($E11,'Freight Rates'!$A$5:$A$13,1),MATCH(U$4,'Freight Rates'!$B$4:$H$4,0)),0))-((Assumptions!$C$63*($A11*Assumptions!$C$8)/100)*Assumptions!$C$64+Assumptions!$C$65))/(Assumptions!$C$63*($A11*Assumptions!$C$8)/100),0) -> 0.2343914
A12: 60 | B12: =$A12*Assumptions!$C$18+Assumptions!$C$34 -> 12.731101 | C12: =$A12*Assumptions!$C$36*(1-Assumptions!$C$33) -> 3402 | D12: =C12/Assumptions!$C$35 -> 24.47482 | E12: =MAX(B12,D12) -> 24.47482 | F12: =$A12*(Assumptions!$C$29+Assumptions!$C$51+Assumptions!$C$52+Assumptions!$C$60)+Assumptions!$C$56+Assumptions!$C$57 -> 18.028655 | G12: =IFERROR(($F12+IFERROR(INDEX('Freight Rates'!$B$5:$H$13,MATCH($E12,'Freight Rates'!$A$5:$A$13,1),MATCH(G$4,'Freight Rates'!$B$4:$H$4,0)),0))/(($A12*Assumptions!$C$8)/100),0) -> 0.16738142 | H12: =IFERROR(($F12+IFERROR(INDEX('Freight Rates'!$B$5:$H$13,MATCH($E12,'Freight Rates'!$A$5:$A$13,1),MATCH(H$4,'Freight Rates'!$B$4:$H$4,0)),0))/(($A12*Assumptions!$C$8)/100),0) -> 0.17293697 | I12: =IFERROR(($F12+IFERROR(INDEX('Freight Rates'!$B$5:$H$13,MATCH($E12,'Freight Rates'!$A$5:$A$13,1),MATCH(I$4,'Freight Rates'!$B$4:$H$4,0)),0))/(($A12*Assumptions!$C$8)/100),0) -> 0.18127031 | J12: =IFERROR(($F12+IFERROR(INDEX('Freight Rates'!$B$5:$H$13,MATCH($E12,'Freight Rates'!$A$5:$A$13,1),MATCH(J$4,'Freight Rates'!$B$4:$H$4,0)),0))/(($A12*Assumptions!$C$8)/100),0) -> 0.19071475 | K12: =IFERROR(($F12+IFERROR(INDEX('Freight Rates'!$B$5:$H$13,MATCH($E12,'Freight Rates'!$A$5:$A$13,1),MATCH(K$4,'Freight Rates'!$B$4:$H$4,0)),0))/(($A12*Assumptions!$C$8)/100),0) -> 0.2001592 | L12: =IFERROR(($F12+IFERROR(INDEX('Freight Rates'!$B$5:$H$13,MATCH($E12,'Freight Rates'!$A$5:$A$13,1),MATCH(L$4,'Freight Rates'!$B$4:$H$4,0)),0))/(($A12*Assumptions!$C$8)/100),0) -> 0.2101592 | M12: =IFERROR(($F12+IFERROR(INDEX('Freight Rates'!$B$5:$H$13,MATCH($E12,'Freight Rates'!$A$5:$A$13,1),MATCH(M$4,'Freight Rates'!$B$4:$H$4,0)),0))/(($A12*Assumptions!$C$8)/100),0) -> 0.22071475 | O12: =IFERROR(((Assumptions!$C$63*($A12*Assumptions!$C$8)/100)-($F12+IFERROR(INDEX('Freight Rates'!$B$5:$H$13,MATCH($E12,'Freight Rates'!$A$5:$A$13,1),MATCH(O$4,'Freight Rates'!$B$4:$H$4,0)),0))-((Assumptions!$C$63*($A12*Assumptions!$C$8)/100)*Assumptions!$C$64+Assumptions!$C$65))/(Assumptions!$C$63*($A12*Assumptions!$C$8)/100),0) -> 0.44272473 | P12: =IFERROR(((Assumptions!$C$63*($A12*Assumptions!$C$8)/100)-($F12+IFERROR(INDEX('Freight Rates'!$B$5:$H$13,MATCH($E12,'Freight Rates'!$A$5:$A$13,1),MATCH(P$4,'Freight Rates'!$B$4:$H$4,0)),0))-((Assumptions!$C$63*($A12*Assumptions!$C$8)/100)*Assumptions!$C$64+Assumptions!$C$65))/(Assumptions!$C$63*($A12*Assumptions!$C$8)/100),0) -> 0.42536362 | Q12: =IFERROR(((Assumptions!$C$63*($A12*Assumptions!$C$8)/100)-($F12+IFERROR(INDEX('Freight Rates'!$B$5:$H$13,MATCH($E12,'Freight Rates'!$A$5:$A$13,1),MATCH(Q$4,'Freight Rates'!$B$4:$H$4,0)),0))-((Assumptions!$C$63*($A12*Assumptions!$C$8)/100)*Assumptions!$C$64+Assumptions!$C$65))/(Assumptions!$C$63*($A12*Assumptions!$C$8)/100),0) -> 0.39932196 | R12: =IFERROR(((Assumptions!$C$63*($A12*Assumptions!$C$8)/100)-($F12+IFERROR(INDEX('Freight Rates'!$B$5:$H$13,MATCH($E12,'Freight Rates'!$A$5:$A$13,1),MATCH(R$4,'Freight Rates'!$B$4:$H$4,0)),0))-((Assumptions!$C$63*($A12*Assumptions!$C$8)/100)*Assumptions!$C$64+Assumptions!$C$65))/(Assumptions!$C$63*($A12*Assumptions!$C$8)/100),0) -> 0.36980807 | S12: =IFERROR(((Assumptions!$C$63*($A12*Assumptions!$C$8)/100)-($F12+IFERROR(INDEX('Freight Rates'!$B$5:$H$13,MATCH($E12,'Freight Rates'!$A$5:$A$13,1),MATCH(S$4,'Freight Rates'!$B$4:$H$4,0)),0))-((Assumptions!$C$63*($A12*Assumptions!$C$8)/100)*Assumptions!$C$64+Assumptions!$C$65))/(Assumptions!$C$63*($A12*Assumptions!$C$8)/100),0) -> 0.34029418 | T12: =IFERROR(((Assumptions!$C$63*($A12*Assumptions!$C$8)/100)-($F12+IFERROR(INDEX('Freight Rates'!$B$5:$H$13,MATCH($E12,'Freight Rates'!$A$5:$A$13,1),MATCH(T$4,'Freight Rates'!$B$4:$H$4,0)),0))-((Assumptions!$C$63*($A12*Assumptions!$C$8)/100)*Assumptions!$C$64+Assumptions!$C$65))/(Assumptions!$C$63*($A12*Assumptions!$C$8)/100),0) -> 0.30904418 | U12: =IFERROR(((Assumptions!$C$63*($A12*Assumptions!$C$8)/100)-($F12+IFERROR(INDEX('Freight Rates'!$B$5:$H$13,MATCH($E12,'Freight Rates'!$A$5:$A$13,1),MATCH(U$4,'Freight Rates'!$B$4:$H$4,0)),0))-((Assumptions!$C$63*($A12*Assumptions!$C$8)/100)*Assumptions!$C$64+Assumptions!$C$65))/(Assumptions!$C$63*($A12*Assumptions!$C$8)/100),0) -> 0.27605807
A14: READING THIS GRID:
A15: - Move DOWN a column: bigger packs spread the fixed pick/pack and parcel cost over more sheets. This is why a 4-pack cannot be dropshipped profitably.
A16: - Move RIGHT across a row: the same pack costs materially more to deliver cross-country. Splitting inventory East + West pulls most orders back into the left-hand columns.
A17: - Any margin cell below ~25% will not fund customer acquisition. Fix it with pack size or compression before touching price.
A18: - Column A is editable - change the pack sizes to whatever you actually intend to sell.

Sheet Scenario - Volume
A1: SCENARIO: ORDER VOLUME x FREIGHT MODE
A2: Procurement view. How landed cost per roll and total capital outlay move with order size and inbound freight mode.
A4: Order size (rolls) | B4: Pallets | C4: Goods cost | D4: LTL $/roll | E4: TL $/roll | F4: Ocean $/roll | G4: Landed $/roll (best mode) | H4: Capital outlay | I4: Notes
A5: 500 | B5: =IFERROR($A5/Assumptions!$C$44,0) -> 0.26041667 | C5: =$A5*Assumptions!$C$29 -> 86.464756 | D5: =IFERROR(Assumptions!$C$46*MAX(1,ROUNDUP($A5/Assumptions!$C$44,0))/$A5,0) -> 0.5 | E5: =IFERROR(Assumptions!$C$47*MAX(1,ROUNDUP($A5/(Assumptions!$C$45*Assumptions!$C$44),0))/$A5,0) -> 5.6 | F5: =IFERROR(Assumptions!$C$49*MAX(1,ROUNDUP($A5/Assumptions!$C$48,0))/$A5+Assumptions!$C$29*Assumptions!$C$50,0) -> 8 | G5: =Assumptions!$C$29+MIN(D5,E5,F5) -> 0.67292951 | H5: =$A5*G5 -> 336.46476 | I5: Sample / pilot run. Non-wholesale pricing - expect a premium.
A6: 1000 | B6: =IFERROR($A6/Assumptions!$C$44,0) -> 0.52083333 | C6: =$A6*Assumptions!$C$29 -> 172.92951 | D6: =IFERROR(Assumptions!$C$46*MAX(1,ROUNDUP($A6/Assumptions!$C$44,0))/$A6,0) -> 0.25 | E6: =IFERROR(Assumptions!$C$47*MAX(1,ROUNDUP($A6/(Assumptions!$C$45*Assumptions!$C$44),0))/$A6,0) -> 2.8 | F6: =IFERROR(Assumptions!$C$49*MAX(1,ROUNDUP($A6/Assumptions!$C$48,0))/$A6+Assumptions!$C$29*Assumptions!$C$50,0) -> 4 | G6: =Assumptions!$C$29+MIN(D6,E6,F6) -> 0.42292951 | H6: =$A6*G6 -> 422.92951 | I6: Small pilot. Enough to test packaging and messaging.
A7: 5000 | B7: =IFERROR($A7/Assumptions!$C$44,0) -> 2.6041667 | C7: =$A7*Assumptions!$C$29 -> 864.64756 | D7: =IFERROR(Assumptions!$C$46*MAX(1,ROUNDUP($A7/Assumptions!$C$44,0))/$A7,0) -> 0.15 | E7: =IFERROR(Assumptions!$C$47*MAX(1,ROUNDUP($A7/(Assumptions!$C$45*Assumptions!$C$44),0))/$A7,0) -> 0.56 | F7: =IFERROR(Assumptions!$C$49*MAX(1,ROUNDUP($A7/Assumptions!$C$48,0))/$A7+Assumptions!$C$29*Assumptions!$C$50,0) -> 0.8 | G7: =Assumptions!$C$29+MIN(D7,E7,F7) -> 0.32292951 | H7: =$A7*G7 -> 1614.6476 | I7: Approaching the wholesale threshold. Push for 10k pricing.
A8: 10000 | B8: =IFERROR($A8/Assumptions!$C$44,0) -> 5.2083333 | C8: =$A8*Assumptions!$C$29 -> 1729.2951 | D8: =IFERROR(Assumptions!$C$46*MAX(1,ROUNDUP($A8/Assumptions!$C$44,0))/$A8,0) -> 0.15 | E8: =IFERROR(Assumptions!$C$47*MAX(1,ROUNDUP($A8/(Assumptions!$C$45*Assumptions!$C$44),0))/$A8,0) -> 0.28 | F8: =IFERROR(Assumptions!$C$49*MAX(1,ROUNDUP($A8/Assumptions!$C$48,0))/$A8+Assumptions!$C$29*Assumptions!$C$50,0) -> 0.4 | G8: =Assumptions!$C$29+MIN(D8,E8,F8) -> 0.32292951 | H8: =$A8*G8 -> 3229.2951 | I8: WHOLESALE PRICING THRESHOLD. Most converters price real wholesale here. ~333 x 30-roll packs.
A9: 20000 | B9: =IFERROR($A9/Assumptions!$C$44,0) -> 10.416667 | C9: =$A9*Assumptions!$C$29 -> 3458.5902 | D9: =IFERROR(Assumptions!$C$46*MAX(1,ROUNDUP($A9/Assumptions!$C$44,0))/$A9,0) -> 0.1375 | E9: =IFERROR(Assumptions!$C$47*MAX(1,ROUNDUP($A9/(Assumptions!$C$45*Assumptions!$C$44),0))/$A9,0) -> 0.14 | F9: =IFERROR(Assumptions!$C$49*MAX(1,ROUNDUP($A9/Assumptions!$C$48,0))/$A9+Assumptions!$C$29*Assumptions!$C$50,0) -> 0.2 | G9: =Assumptions!$C$29+MIN(D9,E9,F9) -> 0.31042951 | H9: =$A9*G9 -> 6208.5902 | I9: Comfortable first production run with proven demand.
A10: 49920 | B10: =IFERROR($A10/Assumptions!$C$44,0) -> 26 | C10: =$A10*Assumptions!$C$29 -> 8632.6412 | D10: =IFERROR(Assumptions!$C$46*MAX(1,ROUNDUP($A10/Assumptions!$C$44,0))/$A10,0) -> 0.13020833 | E10: =IFERROR(Assumptions!$C$47*MAX(1,ROUNDUP($A10/(Assumptions!$C$45*Assumptions!$C$44),0))/$A10,0) -> 0.056089744 | F10: =IFERROR(Assumptions!$C$49*MAX(1,ROUNDUP($A10/Assumptions!$C$48,0))/$A10+Assumptions!$C$29*Assumptions!$C$50,0) -> 0.080128205 | G10: =Assumptions!$C$29+MIN(D10,E10,F10) -> 0.22901926 | H10: =$A10*G10 -> 11432.641 | I10: One full 53ft truckload (26 pallets x 1,920 rolls).
A11: 56160 | B11: =IFERROR($A11/Assumptions!$C$44,0) -> 29.25 | C11: =$A11*Assumptions!$C$29 -> 9711.7214 | D11: =IFERROR(Assumptions!$C$46*MAX(1,ROUNDUP($A11/Assumptions!$C$44,0))/$A11,0) -> 0.13354701 | E11: =IFERROR(Assumptions!$C$47*MAX(1,ROUNDUP($A11/(Assumptions!$C$45*Assumptions!$C$44),0))/$A11,0) -> 0.0997151 | F11: =IFERROR(Assumptions!$C$49*MAX(1,ROUNDUP($A11/Assumptions!$C$48,0))/$A11+Assumptions!$C$29*Assumptions!$C$50,0) -> 0.071225071 | G11: =Assumptions!$C$29+MIN(D11,E11,F11) -> 0.24415458 | H11: =$A11*G11 -> 13711.721 | I11: One full 40ft ocean container.
A12: 99840 | B12: =IFERROR($A12/Assumptions!$C$44,0) -> 52 | C12: =$A12*Assumptions!$C$29 -> 17265.282 | D12: =IFERROR(Assumptions!$C$46*MAX(1,ROUNDUP($A12/Assumptions!$C$44,0))/$A12,0) -> 0.13020833 | E12: =IFERROR(Assumptions!$C$47*MAX(1,ROUNDUP($A12/(Assumptions!$C$45*Assumptions!$C$44),0))/$A12,0) -> 0.056089744 | F12: =IFERROR(Assumptions!$C$49*MAX(1,ROUNDUP($A12/Assumptions!$C$48,0))/$A12+Assumptions!$C$29*Assumptions!$C$50,0) -> 0.080128205 | G12: =Assumptions!$C$29+MIN(D12,E12,F12) -> 0.22901926 | H12: =$A12*G12 -> 22865.282 | I12: Two truckloads. Negotiate a annual volume agreement at this level.
A14: PARTIAL LOADS ROUND UP. A 500-roll order still pays for a whole pallet, so its freight per roll is punishing. This is the real reason small first runs cost more than the quoted per-roll price suggests.
A15: The Assumptions tab uses the steady-state FULL-LOAD rate. This tab shows what your FIRST order actually costs. Use this tab for the go/no-go decision on run size.
A17: IMPORTANT - 'best mode' is a pure cost comparison and ignores feasibility.
A18: - LTL / TL only make sense for a domestic converter. OCEAN only for an offshore one, and only with duty entered on the Assumptions tab.
A19: - Ocean looks cheap per roll at container scale, but a 40ft container is ~$11k of goods against ~$3-5k of freight - a 30-45% freight burden, plus 6-10 weeks of lead time and tied-up cash.
A20: - Recommendation: quote both, let the landed number decide, but weight domestic heavily for a first run. Speed and low MOQ are worth more than a cent per roll while you are still testing the brand.
A21: - MOQ market range is 500 to 250,000 rolls; most converters price wholesale at 10,000+. Your minimum viable first run is roughly $2,000-$3,000 in goods plus plate/artwork fees.

Sheet Benchmark
A1: COMPETITIVE BENCHMARK - COST PER 100 SHEETS
A2: Roll counts and 'Mega roll' math are marketing. This is the only honest comparison.
A4: Product | B4: Pack price | C4: Rolls | D4: Sheets/roll | E4: Total sheets | F4: $/100 sheets | G4: vs our brand | H4: Note
A5: Kirkland Signature (Costco) | B5: 20.99 | C5: 30 | D5: 380 | E5: =C5*D5 -> 11400 | F5: =IFERROR(B5/(E5/100),0) -> 0.18412281 | G5: =IFERROR(F5-$F$9,0) -> -0.072703056 | H5: Warehouse floor price. Requires membership and a car - that gap is your opening.
A6: AmazonCommercial Ultra Strong | B6: 18.54 | C6: 36 | D6: 286 | E6: =C6*D6 -> 10296 | F6: =IFERROR(B6/(E6/100),0) -> 0.18006993 | G6: =IFERROR(F6-$F$9,0) -> -0.076755933 | H6: 36-pack, Subscribe & Save price. Your closest true competitor.
A7: Typical grocery store brand | B7: 12.99 | C7: 12 | D7: 264 | E7: =C7*D7 -> 3168 | F7: =IFERROR(B7/(E7/100),0) -> 0.41003788 | G7: =IFERROR(F7-$F$9,0) -> 0.15321202 | H7: Illustrative. Update with your own shelf checks.
A8: Charmin / Cottonelle (national) | B8: 24.99 | C8: 18 | D8: 244 | E8: =C8*D8 -> 4392 | F8: =IFERROR(B8/(E8/100),0) -> 0.56898907 | G8: =IFERROR(F8-$F$9,0) -> 0.31216321 | H8: Illustrative national brand. Update with your own shelf checks.
A9: OUR BRAND (delivered, from model) | B9: ='Landed Cost Model'!$C$31 -> 23.114328 | C9: ='Landed Cost Model'!$C$6 -> 30 | D9: =Assumptions!$C$8 -> 300 | E9: =C9*D9 -> 9000 | F9: =IFERROR(B9/(E9/100),0) -> 0.25682586 | G9: 0 | H9: This is our DELIVERED cost (incl. parcel to the customer). The competitor rows are SHELF prices with no delivery - the comparison is deliberately conservative against us.
A10: OUR BRAND (target retail) | F10: =Assumptions!$C$63 -> 0.32 | H10: Target retail from Assumptions. Should land below every national brand and above the warehouse floor.
A12: SOURCES
A13: Kirkland Signature: 30 rolls x 380 sheets at $20.99 warehouse = $0.184 per 100 sheets.
A14: AmazonCommercial 2-ply Ultra Strong: 36 x 286 sheets at $18.54 with Subscribe & Save = ~$0.18 per 100 sheets (Slickdeals listings, 2026).
A15: Category context: store brands commonly match premium quality at 30-50% less (Everyday Cheapskate; Who Gives A Crap cost-per-sheet analysis).
A16: Grocery store brand and national brand rows are ILLUSTRATIVE placeholders - replace with your own shelf checks before relying on them.
